{"logs": [{"2021-09-01 20:04:35": {"message": "500 Server Error: Internal Server Error for url: http://localhost:4000/api/users/1/subscriptions", "type": "<class 'requests.exceptions.HTTPError'>", "stack_trace": "Traceback (most recent call last):\n   File \"C:\\Users\\Olamileke\\Desktop\\Code\\Python\\yeetbot\\command_handlers\\list.py\", line 16, in list_handler\n    response = fetch_subscriptions(user[\"id\"])\n   File \"C:\\Users\\Olamileke\\Desktop\\Code\\Python\\yeetbot\\utilities\\api.py\", line 31, in fetch_subscriptions\n    response.raise_for_status()\n   File \"C:\\Users\\Olamileke\\Desktop\\Code\\Python\\yeetbot\\venv\\lib\\site-packages\\requests\\models.py\", line 943, in raise_for_status\n    raise HTTPError(http_error_msg, response=self)\n requests.exceptions.HTTPError: 500 Server Error: Internal Server Error for url: http://localhost:4000/api/users/1/subscriptions\n"}}]}